Workbook

Sheet 1-50
A1: Item ID | B1: Query Type | C1: Difficulty | D1: Legal Domain | E1: Question | F1: Reference Answer | G1: Constitutional Articles | H1: Supporting Passage(s) | I1: Annotattion Type | J1: Annotation Date | K1: Reviewer IDs | L1: Reviever 1: Chathuri Madushika (LLB ousl) | Q1: Reviever 2: Rohana Dasanayaka (LLB ousl) | V1: Reviever 3: Dulani Kulasooriya (LLB ousl) | AA1: Reviever 4: Dulshan Liyanaarachchi (LLB ousl) | AF1: Reviever 5: Inoshika Kodithuwakku (LLB ousl) | AK1: Mean | AL1: Mean | AM1: Mean
L2: Reviewer ID: LEGAL_EXPERT_1 | Q2: Reviewer ID: LEGAL_EXPERT_2 | V2: Reviewer ID: LEGAL_EXPERT_3 | AA2: Reviewer ID: LEGAL_EXPERT_4 | AF2: Reviewer ID: LEGAL_EXPERT_5 | AK2: Reviewer IDs: LEGAL_EXPERT_1, LEGAL_EXPERT_2, LEGAL_EXPERT_3, LEGAL_EXPERT_4, LEGAL_EXPERT_5
L3: Correctness (1=Poor 5=Excellent) | M3: Completeness (1=Poor 5=Excellent) | N3: Clarity (1=Poor 5=Excellent) | O3: Expert Comments | P3: Review Date | Q3: Correctness (1=Poor 5=Excellent) | R3: Completeness (1=Poor 5=Excellent) | S3: Clarity (1=Poor 5=Excellent) | T3: Expert Comments | U3: Review Date | V3: Correctness (1=Poor 5=Excellent) | W3: Completeness (1=Poor 5=Excellent) | X3: Clarity (1=Poor 5=Excellent) | Y3: Expert Comments | Z3: Review Date | AA3: Correctness (1=Poor 5=Excellent) | AB3: Completeness (1=Poor 5=Excellent) | AC3: Clarity (1=Poor 5=Excellent) | AD3: Expert Comments | AE3: Review Date | AF3: Correctness (1=Poor 5=Excellent) | AG3: Completeness (1=Poor 5=Excellent) | AH3: Clarity (1=Poor 5=Excellent) | AI3: Expert Comments | AJ3: Review Date | AK3: Correctness (1=Poor 5=Excellent) | AL3: Completeness (1=Poor 5=Excellent) | AM3: Clarity (1=Poor 5=Excellent)
A4: QAC_001 | B4: Factual | C4: Easy | D4: Administrative | E4: What is the constitutional status and form of government of Sri Lanka? | F4: According to Article 1 of the Constitution, Sri Lanka (Ceylon) is a Free, Sovereign, Independent and Democratic Socialist Republic and shall be known as the Democratic Socialist Republic of Sri Lanka. Article 2 further declares that the Republic of Sri Lanka is a Unitary State. | G4: Article 1, Article 2 | H4: Art. 1: Sri Lanka (Ceylon) is a Free, Sovereign, The State Independent and Democratic Socialist Republic and shall be known as the Democratic Socialist Republic of Sri Lanka. || Art. 2: The Republic of Sri Lanka is a Unitary State. Unitary State | I4: Human Annotated | J4: =MAX(P4,U4,Z4,AE4,AJ4) -> 46170 | K4: LEGAL_EXPERT_1, LEGAL_EXPERT_2, LEGAL_EXPERT_3, LEGAL_EXPERT_4, LEGAL_EXPERT_5 | L4: 4.8 | M4: 4.5 | N4: 4.6 | P4: 2026.05.24 | Q4: 4.7 | R4: 4.6 | S4: 4.6 | U4: 46168 | V4: 4.7 | W4: 4.7 | X4: 4.6 | Z4: 46168 | AA4: 4.7 | AB4: 4.8 | AC4: 4.7 | AE4: 46170 | AF4: 4.7 | AG4: 4.6 | AH4: 4.7 | AJ4: 2026.05.28 | AK4: =AVERAGE(L4,Q4,V4,AA4,AF4) -> 4.72 | AL4: =AVERAGE(M4,R4,W4,AB4,AG4) -> 4.64 | AM4: =AVERAGE(N4,S4,X4,AC4,AH4) -> 4.64
A5: QAC_002 | B5: Factual | C5: Easy | D5: Administrative | E5: Where does sovereignty reside under the Constitution of Sri Lanka? | F5: Article 3 of the Constitution declares that in the Republic of Sri Lanka, sovereignty is in the People and is inalienable. Sovereignty includes the powers of government, fundamental rights and the franchise. | G5: Article 3 | H5: Art. 3: In the Republic of Sri Lanka sovereignty is Sovereignty in the People and is inalienable. Sovereignty includes the of the People powers of government, fundamental rights and the franchise. | I5: Human Annotated | J5: =MAX(P5,U5,Z5,AE5,AJ5) -> 46170 | K5: LEGAL_EXPERT_1, LEGAL_EXPERT_2, LEGAL_EXPERT_3, LEGAL_EXPERT_4, LEGAL_EXPERT_5 | L5: 4.8 | M5: 4.3 | N5: 4.6 | P5: 2026.05.24 | Q5: 4.8 | R5: 4.4 | S5: 4.5 | U5: 46168 | V5: 4.3 | W5: 4.4 | X5: 4.6 | Z5: 46168 | AA5: 4.4 | AB5: 4.5 | AC5: 4.6 | AE5: 46170 | AF5: 4.7 | AG5: 4.6 | AH5: 4.7 | AJ5: 2026.05.28 | AK5: =AVERAGE(L5,Q5,V5,AA5,AF5) -> 4.6 | AL5: =AVERAGE(M5,R5,W5,AB5,AG5) -> 4.44 | AM5: =AVERAGE(N5,S5,X5,AC5,AH5) -> 4.6
A6: QAC_003 | B6: Factual | C6: Easy | D6: Administrative | E6: What is the constitutional status of Buddhism in Sri Lanka? | F6: Article 9 of the Constitution gives Buddhism the foremost place in Sri Lanka. It shall be the duty of the State to protect and foster the Buddha Sasana, while assuring to all religions the rights granted by Articles 10 and 14(1)(e) of the Constitution. | G6: Article 9 | H6: Art. 9: The Republic of Sri Lanka shall give to Buddhism Buddhism the foremost place and accordingly it shall be the duty of the State to protect and foster the Buddha Sasana, while assuring to all religions | I6: Human Annotated | J6: =MAX(P6,U6,Z6,AE6,AJ6) -> 46170 | K6: LEGAL_EXPERT_1, LEGAL_EXPERT_2, LEGAL_EXPERT_3, LEGAL_EXPERT_4, LEGAL_EXPERT_5 | L6: 4.8 | M6: 4.3 | N6: 4.6 | P6: 2026.05.24 | Q6: 4.7 | R6: 4.4 | S6: 4.6 | U6: 46168 | V6: 4.6 | W6: 4.4 | X6: 4.7 | Z6: 46168 | AA6: 4.6 | AB6: 4.7 | AC6: 4.5 | AE6: 46170 | AF6: 4.7 | AG6: 4.6 | AH6: 4.7 | AJ6: 2026.05.28 | AK6: =AVERAGE(L6,Q6,V6,AA6,AF6) -> 4.68 | AL6: =AVERAGE(M6,R6,W6,AB6,AG6) -> 4.48 | AM6: =AVERAGE(N6,S6,X6,AC6,AH6) -> 4.62
A7: QAC_004 | B7: Factual | C7: Easy | D7: Administrative | E7: What is the right to freedom of thought, conscience and religion under the Constitution? | F7: Article 10 of the Constitution guarantees that every person is entitled to freedom of thought, conscience and religion, including the freedom to have or to adopt a religion or belief of his choice. | G7: Article 10 | H7: Art. 10: Every person is entitled to freedom of thought, thought, conscience and religion, including the freedom to have or conscience and religion to adopt a religion or belief of his choice. Freedom | I7: Human Annotated | J7: =MAX(P7,U7,Z7,AE7,AJ7) -> 46170 | K7: LEGAL_EXPERT_1, LEGAL_EXPERT_2, LEGAL_EXPERT_3, LEGAL_EXPERT_4, LEGAL_EXPERT_5 | L7: 4.8 | M7: 4.3 | N7: 4.6 | P7: 2026.05.24 | Q7: 4.8 | R7: 4.5 | S7: 4.5 | U7: 46168 | V7: 4.7 | W7: 4.4 | X7: 4.5 | Z7: 46168 | AA7: 4.9 | AB7: 4.8 | AC7: 4.7 | AE7: 46170 | AF7: 4.7 | AG7: 4.6 | AH7: 4.7 | AJ7: 2026.05.28 | AK7: =AVERAGE(L7,Q7,V7,AA7,AF7) -> 4.78 | AL7: =AVERAGE(M7,R7,W7,AB7,AG7) -> 4.52 | AM7: =AVERAGE(N7,S7,X7,AC7,AH7) -> 4.6
A8: QAC_005 | B8: Factual | C8: Easy | D8: Administrative | E8: What does the Constitution say about protection from torture and cruel treatment? | F8: Article 11 of the Constitution provides that no person shall be subjected to torture or to cruel, inhuman or degrading treatment or punishment. This is an absolute protection with no exceptions or qualifications. | G8: Article 11 | H8: Art. 11: No person shall be subjected to torture or to from torture cruel, inhuman or degrading treatment or punishment. Right to | I8: Human Annotated | J8: =MAX(P8,U8,Z8,AE8,AJ8) -> 46170 | K8: LEGAL_EXPERT_1, LEGAL_EXPERT_2, LEGAL_EXPERT_3, LEGAL_EXPERT_4, LEGAL_EXPERT_5 | L8: 4.8 | M8: 4.3 | N8: 4.6 | P8: 2026.05.24 | Q8: 4.7 | R8: 4.3 | S8: 4.6 | U8: 46168 | V8: 4.6 | W8: 4.4 | X8: 4.7 | Z8: 46168 | AA8: 4.5 | AB8: 4.4 | AC8: 4.8 | AE8: 46170 | AF8: 4.7 | AG8: 4.6 | AH8: 4.7 | AJ8: 2026.05.28 | AK8: =AVERAGE(L8,Q8,V8,AA8,AF8) -> 4.66 | AL8: =AVERAGE(M8,R8,W8,AB8,AG8) -> 4.4 | AM8: =AVERAGE(N8,S8,X8,AC8,AH8) -> 4.68
A9: QAC_006 | B9: Factual | C9: Medium | D9: Administrative | E9: What is the right to equality before the law in Sri Lanka? | F9: Article 12 of the Constitution provides that all persons are equal before the law and are entitled to the equal protection of the law. Under Article 12(2), no citizen shall be discriminated against on the grounds of race, religion, language, caste, sex, political opinion, place of birth or any one of such grounds. Article 12(3) further provides that no person shall, on such grounds, be subject to any disability, liability, restriction or condition with regard to access to shops, public restaurants, hotels, places of public entertainment and places of public worship of his own religion. | G9: Article 12, Article 12, Article 12 | H9: Art. 12: (1) All persons are equal before the law and are equality entitled to the equal protection of the law. (2) No citizen shall be discriminated against on the grounds of race, religion, language, caste, || Art. 12: (1) All persons are equal before the law and are equality entitled to the equal protection of the law. (2) No citizen shall be discriminated against on the grounds of race, religion, language, caste, || Art. 12: (1) All persons are equal before the law and are equality entitled to the equal protection of the law. (2) No citizen shall be discriminated against on the grounds of race, religion, language, caste, | I9: Human Annotated | J9: =MAX(P9,U9,Z9,AE9,AJ9) -> 46170 | K9: LEGAL_EXPERT_1, LEGAL_EXPERT_2, LEGAL_EXPERT_3, LEGAL_EXPERT_4, LEGAL_EXPERT_5 | L9: 4.8 | M9: 4.3 | N9: 4.6 | P9: 2026.05.24 | Q9: 4.8 | R9: 4.3 | S9: 4.6 | U9: 46168 | V9: 4.8 | W9: 4.4 | X9: 4.5 | Z9: 46168 | AA9: 4.7 | AB9: 4.5 | AC9: 4.5 | AE9: 46170 | AF9: 4.7 | AG9: 4.6 | AH9: 4.7 | AJ9: 2026.05.28 | AK9: =AVERAGE(L9,Q9,V9,AA9,AF9) -> 4.76 | AL9: =AVERAGE(M9,R9,W9,AB9,AG9) -> 4.42 | AM9: =AVERAGE(N9,S9,X9,AC9,AH9) -> 4.58
A10: QAC_007 | B10: Factual | C10: Medium | D10: Criminal | E10: What constitutional rights apply to a person who is arrested or detained? | F10: Article 13 of the Constitution provides that every person held in custody, detained or otherwise deprived of personal liberty shall be brought before the judge of the nearest competent court according to procedure established by law, and shall not be further held in custody, detained or deprived of personal liberty except upon and in terms of the order of such judge. Article 13(5) also establishes the presumption of innocence: every person shall be presumed innocent until proved guilty. | G10: Article 13, Article 13 | H10: Art. 13: (1) No person shall be arrested except according Freedom from to procedure established by law. Any person arrested shall arbitrary arrest, be informed of the reason for his arrest. detention and punis || Art. 13: (1) No person shall be arrested except according Freedom from to procedure established by law. Any person arrested shall arbitrary arrest, be informed of the reason for his arrest. detention and punis | I10: Human Annotated | J10: =MAX(P10,U10,Z10,AE10,AJ10) -> 46170 | K10: LEGAL_EXPERT_1, LEGAL_EXPERT_2, LEGAL_EXPERT_3, LEGAL_EXPERT_4, LEGAL_EXPERT_5 | L10: 4.8 | M10: 4.3 | N10: 4.6 | P10: 2026.05.24 | Q10: 4.9 | R10: 4.4 | S10: 4.6 | U10: 46168 | V10: 4.9 | W10: 4.7 | X10: 4.6 | Z10: 46168 | AA10: 4.7 | AB10: 4.7 | AC10: 4.7 | AE10: 46170 | AF10: 4.7 | AG10: 4.6 | AH10: 4.7 | AJ10: 2026.05.28 | AK10: =AVERAGE(L10,Q10,V10,AA10,AF10) -> 4.8 | AL10: =AVERAGE(M10,R10,W10,AB10,AG10) -> 4.54 | AM10: =AVERAGE(N10,S10,X10,AC10,AH10) -> 4.64
A11: QAC_008 | B11: Factual | C11: Medium | D11: Administrative | E11: What freedoms are protected under Article 14 of the Constitution? | F11: Article 14 of the Constitution protects several fundamental freedoms including: (b) the freedom of peaceful assembly; (c) the freedom of association; (d) the freedom to form and join a trade union; (e) the freedom, either by himself or in association with others, and either in public or in private, to manifest his religion or belief in worship, observance, practice and teaching; and (f) the freedom by himself or in association with others to enjoy and promote his own culture and to use his own language. | G11: Article 14 | H11: Art. 14: (1) Every citizen is entitled to speech, assembly, (a) the freedom of speech and expression association, including publication; occupation, movement, & c. (b) the freedom of peaceful assembly; (c) th | I11: Human Annotated | J11: =MAX(P11,U11,Z11,AE11,AJ11) -> 46170 | K11: LEGAL_EXPERT_1, LEGAL_EXPERT_2, LEGAL_EXPERT_3, LEGAL_EXPERT_4, LEGAL_EXPERT_5 | L11: 4.8 | M11: 4.3 | N11: 4.6 | P11: 2026.05.24 | Q11: 4.8 | R11: 4.4 | S11: 4.5 | U11: 46168 | V11: 4.8 | W11: 4.5 | X11: 4.6 | Z11: 46168 | AA11: 4.5 | AB11: 4.5 | AC11: 4.7 | AE11: 46170 | AF11: 4.7 | AG11: 4.6 | AH11: 4.7 | AJ11: 2026.05.28 | AK11: =AVERAGE(L11,Q11,V11,AA11,AF11) -> 4.72 | AL11: =AVERAGE(M11,R11,W11,AB11,AG11) -> 4.46 | AM11: =AVERAGE(N11,S11,X11,AC11,AH11) -> 4.62
A12: QAC_009 | B12: Procedural | C12: Medium | D12: Administrative | E12: How can a person enforce their fundamental rights in Sri Lanka? | F12: Under Article 17 of the Constitution, every person shall be entitled to apply to the Supreme Court, as provided by Article 126, in respect of the infringement or imminent infringement, by executive or administrative action, of a fundamental right to which such person is entitled under the provisions of Chapter III of the Constitution. | G12: Article 17 | H12: Art. 17: Every person shall be entitled to apply to the for the Supreme Court, as provided by Article 126, in respect of infringement of the infringement or imminent infringement, by executive fundamental righ | I12: Human Annotated | J12: =MAX(P12,U12,Z12,AE12,AJ12) -> 46170 | K12: LEGAL_EXPERT_1, LEGAL_EXPERT_2, LEGAL_EXPERT_3, LEGAL_EXPERT_4, LEGAL_EXPERT_5 | L12: 4.8 | M12: 4.3 | N12: 4.6 | P12: 2026.05.24 | Q12: 4.6 | R12: 4.3 | S12: 4.6 | U12: 46168 | V12: 4.5 | W12: 4.2 | X12: 4.5 | Z12: 46168 | AA12: 4.7 | AB12: 4.6 | AC12: 4.5 | AE12: 46170 | AF12: 4.7 | AG12: 4.6 | AH12: 4.7 | AJ12: 2026.05.28 | AK12: =AVERAGE(L12,Q12,V12,AA12,AF12) -> 4.66 | AL12: =AVERAGE(M12,R12,W12,AB12,AG12) -> 4.4 | AM12: =AVERAGE(N12,S12,X12,AC12,AH12) -> 4.58
A13: QAC_010 | B13: Factual | C13: Easy | D13: Administrative | E13: What are the National Languages of Sri Lanka under the Constitution? | F13: Article 19 of the Constitution provides that the National Languages of Sri Lanka shall be Sinhala and Tamil. Article 20 further provides that a Member of Parliament or a member of a Provincial Council or a Local Authority shall be entitled to perform his duties and discharge his functions in Parliament in either National Language. | G13: Article 19 | H13: Art. 19: The National Languages of Sri Lanka shall be National Languages Sinhala and Tamil. | I13: Human Annotated | J13: =MAX(P13,U13,Z13,AE13,AJ13) -> 46170 | K13: LEGAL_EXPERT_1, LEGAL_EXPERT_2, LEGAL_EXPERT_3, LEGAL_EXPERT_4, LEGAL_EXPERT_5 | L13: 4.8 | M13: 4.3 | N13: 4.6 | P13: 2026.05.24 | Q13: 4.7 | R13: 4.4 | S13: 4.6 | U13: 46168 | V13: 4.6 | W13: 4.5 | X13: 4.6 | Z13: 46168 | AA13: 4.5 | AB13: 4.5 | AC13: 4.5 | AE13: 46170 | AF13: 4.7 | AG13: 4.6 | AH13: 4.7 | AJ13: 2026.05.28 | AK13: =AVERAGE(L13,Q13,V13,AA13,AF13) -> 4.66 | AL13: =AVERAGE(M13,R13,W13,AB13,AG13) -> 4.46 | AM13: =AVERAGE(N13,S13,X13,AC13,AH13) -> 4.6
A14: QAC_011 | B14: Factual | C14: Medium | D14: Administrative | E14: What are the Directive Principles of State Policy and who are they binding on? | F14: Article 27(1) of the Constitution provides that the Directive Principles of State Policy shall guide Parliament, the President and the Cabinet of Ministers in the enactment of laws and the governance of Sri Lanka for the establishment of a just and free society. However, Article 29 makes clear that these provisions do not confer or impose legal rights or obligations and are not enforceable in any court or tribunal. | G14: Article 27, Article 29 | H14: Art. 27: (1) The Directive Principles of State Policy Directive Principles herein contained shall guide Parliament, the President of State and the Cabinet of Ministers in the enactment of laws and Policy the g || Art. 29: The provisions of this Chapter do not confer or Principles of State impose legal rights or obligations and are not enforceable Policy and in any court or tribunal. No question of inconsistency fundame | I14: Human Annotated | J14: =MAX(P14,U14,Z14,AE14,AJ14) -> 46170 | K14: LEGAL_EXPERT_1, LEGAL_EXPERT_2, LEGAL_EXPERT_3, LEGAL_EXPERT_4, LEGAL_EXPERT_5 | L14: 4.8 | M14: 4.3 | N14: 4.6 | P14: 2026.05.24 | Q14: 4.7 | R14: 4.4 | S14: 4.6 | U14: 46168 | V14: 4.5 | W14: 4.4 | X14: 4.6 | Z14: 46168 | AA14: 4.4 | AB14: 4.6 | AC14: 4.6 | AE14: 46170 | AF14: 4.7 | AG14: 4.6 | AH14: 4.7 | AJ14: 2026.05.28 | AK14: =AVERAGE(L14,Q14,V14,AA14,AF14) -> 4.62 | AL14: =AVERAGE(M14,R14,W14,AB14,AG14) -> 4.46 | AM14: =AVERAGE(N14,S14,X14,AC14,AH14) -> 4.62
A15: QAC_012 | B15: Factual | C15: Medium | D15: Administrative | E15: What does the Constitution say about the State's obligation to establish a democratic socialist society? | F15: Article 27(2) of the Constitution provides that the State is pledged to establish in Sri Lanka a Democratic Socialist Society, the objectives of which include: (a) the full realization of the fundamental rights and freedoms of all persons; (b) the promotion of the welfare of the People by securing and protecting as effectively as may be a social order in which justice (social, economic and political) shall guide all the institutions of the national life. | G15: Article 27 | H15: Art. 27: (2) The State is pledged to establish in Sri Lanka a Democratic Socialist Society, the objectives of which include (a) the full realization of the fundamental rights and freedoms of all persons; (b) | I15: Human Annotated | J15: =MAX(P15,U15,Z15,AE15,AJ15) -> 46170 | K15: LEGAL_EXPERT_1, LEGAL_EXPERT_2, LEGAL_EXPERT_3, LEGAL_EXPERT_4, LEGAL_EXPERT_5 | L15: 4.8 | M15: 4.3 | N15: 4.6 | P15: 2026.05.24 | Q15: 4.7 | R15: 4.4 | S15: 4.6 | U15: 46168 | V15: 4.6 | W15: 4.5 | X15: 4.7 | Z15: 46168 | AA15: 4.7 | AB15: 4.6 | AC15: 4.5 | AE15: 46170 | AF15: 4.7 | AG15: 4.6 | AH15: 4.7 | AJ15: 2026.05.28 | AK15: =AVERAGE(L15,Q15,V15,AA15,AF15) -> 4.7 | AL15: =AVERAGE(M15,R15,W15,AB15,AG15) -> 4.48 | AM15: =AVERAGE(N15,S15,X15,AC15,AH15) -> 4.62
... A18: QAC_015 | B18: Factual | C18: Medium | D18: Administrative | E18: What constitutional obligations does Sri Lanka have regarding environmental protection? | F18: Article 27(14) of the Constitution provides that the State shall protect, preserve and improve the environment for the benefit of the community. This is a directive principle of state policy under Chapter VI of the Constitution, meaning it guides legislation and governance but is not directly enforceable in courts under Article 29. | G18: Article 27, Article 29 | H18: Art. 27: (11) The State shall create the necessary economic and social environment to enable people of all religious faiths to make a reality of their religious principles. (12) The State shall recognize and p || Art. 29: The provisions of this Chapter do not confer or Principles of State impose legal rights or obligations and are not enforceable Policy and in any court or tribunal. No question of inconsistency fundame | I18: Human Annotated | J18: =MAX(P18,U18,Z18,AE18,AJ18) -> 46170 | K18: LEGAL_EXPERT_1, LEGAL_EXPERT_2, LEGAL_EXPERT_3, LEGAL_EXPERT_4, LEGAL_EXPERT_5 | L18: 4.8 | M18: 4.3 | N18: 4.6 | P18: 2026.05.24 | Q18: 4.7 | R18: 4.4 | S18: 4.5 | U18: 46168 | V18: 4.5 | W18: 4.4 | X18: 4.5 | Z18: 46168 | AA18: 4.4 | AB18: 4.5 | AC18: 4.4 | AE18: 46170 | AF18: 4.7 | AG18: 4.6 | AH18: 4.7 | AJ18: 2026.05.28 | AK18: =AVERAGE(L18,Q18,V18,AA18,AF18) -> 4.62 | AL18: =AVERAGE(M18,R18,W18,AB18,AG18) -> 4.44 | AM18: =AVERAGE(N18,S18,X18,AC18,AH18) -> 4.54
A19: QAC_016 | B19: Factual | C19: Medium | D19: Administrative | E19: What does the Constitution say about Sri Lanka's obligations regarding international peace and cooperation? | F19: Article 27(15) of the Constitution states that the State shall promote international peace, security and co-operation, and the establishment of a just and equitable international economic and social order and shall endeavour to foster respect for international law and treaty obligations in dealings among nations. | G19: Article 27 | H19: Art. 27: (11) The State shall create the necessary economic and social environment to enable people of all religious faiths to make a reality of their religious principles. (12) The State shall recognize and p | I19: Human Annotated | J19: =MAX(P19,U19,Z19,AE19,AJ19) -> 46170 | K19: LEGAL_EXPERT_1, LEGAL_EXPERT_2, LEGAL_EXPERT_3, LEGAL_EXPERT_4, LEGAL_EXPERT_5 | L19: 4.8 | M19: 4.3 | N19: 4.6 | P19: 2026.05.24 | Q19: 4.7 | R19: 4.3 | S19: 4.6 | U19: 46168 | V19: .4.7 | W19: 4.3 | X19: 4.6 | Z19: 46168 | AA19: 4.8 | AB19: 4.5 | AC19: 4.5 | AE19: 46170 | AF19: 4.7 | AG19: 4.6 | AH19: 4.7 | AJ19: 2026.05.28 | AK19: =AVERAGE(L19,Q19,V19,AA19,AF19) -> 4.75 | AL19: =AVERAGE(M19,R19,W19,AB19,AG19) -> 4.4 | AM19: =AVERAGE(N19,S19,X19,AC19,AH19) -> 4.6
A20: QAC_017 | B20: Factual | C20: Medium | D20: Administrative | E20: What are the fundamental duties of citizens under the Constitution of Sri Lanka? | F20: Article 28 of the Constitution provides that the exercise and enjoyment of rights and freedoms are inseparable from the performance of duties and obligations. It is accordingly the duty of every person in Sri Lanka: (a) to uphold and defend the Constitution and the law; (b) to further the national interest and to foster national unity; (c) to work conscientiously in his chosen occupation. These fundamental duties apply alongside the fundamental rights guaranteed in Chapter III. | G20: Article 28, Article 28 | H20: Art. 28: The exercise and enjoyment of rights and Fundamental freedoms are inseparable from the performance of duties duties and obligations and accordingly it is the duty of every person in Sri Lanka (a) to || Art. 28: The exercise and enjoyment of rights and Fundamental freedoms are inseparable from the performance of duties duties and obligations and accordingly it is the duty of every person in Sri Lanka (a) to | I20: Human Annotated | J20: =MAX(P20,U20,Z20,AE20,AJ20) -> 46170 | K20: LEGAL_EXPERT_1, LEGAL_EXPERT_2, LEGAL_EXPERT_3, LEGAL_EXPERT_4, LEGAL_EXPERT_5 | L20: 4.8 | M20: 4.3 | N20: 4.6 | P20: 2026.05.24 | Q20: 4.8 | R20: 4.4 | S20: 4.6 | U20: 46168 | V20: 4.8 | W20: 4.4 | X20: 4.6 | Z20: 46168 | AA20: 4.6 | AB20: 4.5 | AC20: 4.4 | AE20: 46170 | AF20: 4.7 | AG20: 4.6 | AH20: 4.7 | AJ20: 2026.05.28 | AK20: =AVERAGE(L20,Q20,V20,AA20,AF20) -> 4.74 | AL20: =AVERAGE(M20,R20,W20,AB20,AG20) -> 4.44 | AM20: =AVERAGE(N20,S20,X20,AC20,AH20) -> 4.58
A21: QAC_018 | B21: Interpretive | C21: Medium | D21: Administrative | E21: Are the Directive Principles of State Policy legally enforceable in court? | F21: No. Article 29 of the Constitution expressly provides that the provisions of Chapter VI (Directive Principles of State Policy and Fundamental Duties) do not confer or impose legal rights or obligations and are not enforceable in any court or tribunal. No question of inconsistency with such provisions shall be raised in any court or justiciable tribunal. The Directive Principles serve as guides for Parliament, the President and the Cabinet of Ministers in governance, but cannot be directly relied upon in litigation. | G21: Article 29 | H21: Art. 29: The provisions of this Chapter do not confer or Principles of State impose legal rights or obligations and are not enforceable Policy and in any court or tribunal. No question of inconsistency fundame | I21: Human Annotated | J21: =MAX(P21,U21,Z21,AE21,AJ21) -> 46170 | K21: LEGAL_EXPERT_1, LEGAL_EXPERT_2, LEGAL_EXPERT_3, LEGAL_EXPERT_4, LEGAL_EXPERT_5 | L21: 4.8 | M21: 4.3 | N21: 4.6 | P21: 2026.05.24 | Q21: 4.8 | R21: 4.4 | S21: 4.7 | U21: 46168 | V21: 4.7 | W21: 4.4 | X21: 4.7 | Z21: 46168 | AA21: 4.7 | AB21: 4.7 | AC21: 4.7 | AE21: 46170 | AF21: 4.7 | AG21: 4.6 | AH21: 4.7 | AJ21: 2026.05.28 | AK21: =AVERAGE(L21,Q21,V21,AA21,AF21) -> 4.74 | AL21: =AVERAGE(M21,R21,W21,AB21,AG21) -> 4.48 | AM21: =AVERAGE(N21,S21,X21,AC21,AH21) -> 4.68
A22: QAC_019 | B22: Factual | C22: Easy | D22: Criminal | E22: What is the presumption of innocence under Sri Lankan constitutional law? | F22: Article 13(5) of the Constitution provides that every person shall be presumed innocent until he is proved guilty. The burden of proving particular facts may, by law, be placed on an accused person, but this does not negate the general presumption of innocence. | G22: Article 13 | H22: Art. 13: (1) No person shall be arrested except according Freedom from to procedure established by law. Any person arrested shall arbitrary arrest, be informed of the reason for his arrest. detention and punis | I22: Human Annotated | J22: =MAX(P22,U22,Z22,AE22,AJ22) -> 46170 | K22: LEGAL_EXPERT_1, LEGAL_EXPERT_2, LEGAL_EXPERT_3, LEGAL_EXPERT_4, LEGAL_EXPERT_5 | L22: 4.8 | M22: 4.3 | N22: 4.6 | P22: 2026.05.24 | Q22: 4.7 | R22: 4.4 | S22: 4.6 | U22: 46168 | V22: 4.6 | W22: 4.5 | X22: 4.6 | Z22: 46168 | AA22: 4.5 | AB22: 4.4 | AC22: 4.5 | AE22: 46170 | AF22: 4.7 | AG22: 4.6 | AH22: 4.7 | AJ22: 2026.05.28 | AK22: =AVERAGE(L22,Q22,V22,AA22,AF22) -> 4.66 | AL22: =AVERAGE(M22,R22,W22,AB22,AG22) -> 4.44 | AM22: =AVERAGE(N22,S22,X22,AC22,AH22) -> 4.6
A23: QAC_020 | B23: Factual | C23: Easy | D23: Labor | E23: What does the Constitution say about the right to freedom of association and forming trade unions? | F23: Article 14 of the Constitution guarantees the freedom of association and the freedom to form and join a trade union. These rights are protected as fundamental rights under Chapter III of the Constitution. | G23: Article 14 | H23: Art. 14: (1) Every citizen is entitled to speech, assembly, (a) the freedom of speech and expression association, including publication; occupation, movement, & c. (b) the freedom of peaceful assembly; (c) th | I23: Human Annotated | J23: =MAX(P23,U23,Z23,AE23,AJ23) -> 46170 | K23: LEGAL_EXPERT_1, LEGAL_EXPERT_2, LEGAL_EXPERT_3, LEGAL_EXPERT_4, LEGAL_EXPERT_5 | L23: 4.8 | M23: 4.3 | N23: 4.6 | P23: 2026.05.24 | Q23: 4.7 | R23: 4.4 | S23: 4.6 | U23: 46168 | V23: 4.7 | W23: 4.3 | X23: 4.5 | Z23: 46168 | AA23: 4.4 | AB23: 4.3 | AC23: 4.3 | AE23: 46170 | AF23: 4.7 | AG23: 4.6 | AH23: 4.7 | AJ23: 2026.05.28 | AK23: =AVERAGE(L23,Q23,V23,AA23,AF23) -> 4.66 | AL23: =AVERAGE(M23,R23,W23,AB23,AG23) -> 4.38 | AM23: =AVERAGE(N23,S23,X23,AC23,AH23) -> 4.54
A24: QAC_021 | B24: Procedural | C24: Hard | D24: Administrative | E24: How is the Constitution of Sri Lanka amended? | F24: Article 82 of the Constitution provides that no Bill for the amendment of any provision of the Constitution shall be placed on the Order Paper of Parliament, unless the provision to be repealed, altered or added, and consequential amendments, if any, are expressly specified in the Bill and it is described in the long title thereof as being an Act for the amendment of the Constitution. | G24: Article 82 | H24: Art. 82: (1) No Bill for the amendment of any provision Amendment or of the Constitution shall be placed on the Order Paper of repeal of the Constitution Parliament, unless the provision to be repealed, altere | I24: Human Annotated | J24: =MAX(P24,U24,Z24,AE24,AJ24) -> 46170 | K24: LEGAL_EXPERT_1, LEGAL_EXPERT_2, LEGAL_EXPERT_3, LEGAL_EXPERT_4, LEGAL_EXPERT_5 | L24: 4.8 | M24: 4.3 | N24: 4.6 | P24: 2026.05.24 | Q24: 4.8 | R24: 4.4 | S24: 4.6 | U24: 46168 | V24: 4.8 | W24: 4.3 | X24: 4.5 | Z24: 46168 | AA24: 4.5 | AB24: 4.5 | AC24: 4.5 | AE24: 46170 | AF24: 4.7 | AG24: 4.6 | AH24: 4.7 | AJ24: 2026.05.28 | AK24: =AVERAGE(L24,Q24,V24,AA24,AF24) -> 4.72 | AL24: =AVERAGE(M24,R24,W24,AB24,AG24) -> 4.42 | AM24: =AVERAGE(N24,S24,X24,AC24,AH24) -> 4.58
A25: QAC_022 | B25: Factual | C25: Easy | D25: Administrative | E25: What is the National Day and National Anthem of Sri Lanka under the Constitution? | F25: Article 8 of the Constitution provides that the National Day of the Republic of Sri Lanka shall be the fourth day of February. Article 7 provides that the National Anthem of the Republic of Sri Lanka shall be Sri Lanka Matha, the words and music of which are set out in the Third Schedule to the Constitution. | G25: Article 8, Article 7 | H25: Art. 8: The National Day of the Republic of Sri Lanka Day shall be the fourth day of February 1 - Substituted by the Seventh Amendment to the Constitution Sec. 2(a). 2 - Substituted by the Seventh Amendment t || Art. 7: The National Anthem of the Republic of Sri Anthem Lanka shall be Sri Lanka Matha, the words and music of which are set out in the Third Schedule. The National | I25: Human Annotated | J25: =MAX(P25,U25,Z25,AE25,AJ25) -> 46170 | K25: LEGAL_EXPERT_1, LEGAL_EXPERT_2, LEGAL_EXPERT_3, LEGAL_EXPERT_4, LEGAL_EXPERT_5 | L25: 4.8 | M25: 4.3 | N25: 4.6 | P25: 2026.05.24 | Q25: 4.8 | R25: 4.4 | S25: 4.6 | U25: 46168 | V25: 4.8 | W25: 4.4 | X25: 4.6 | Z25: 46168 | AA25: 4.6 | AB25: 4.6 | AC25: 4.7 | AE25: 46170 | AF25: 4.7 | AG25: 4.6 | AH25: 4.7 | AJ25: 2026.05.28 | AK25: =AVERAGE(L25,Q25,V25,AA25,AF25) -> 4.74 | AL25: =AVERAGE(M25,R25,W25,AB25,AG25) -> 4.46 | AM25: =AVERAGE(N25,S25,X25,AC25,AH25) -> 4.64
A26: QAC_023 | B26: Cross_referenced | C26: Hard | D26: Administrative | E26: How does Article 9 on Buddhism relate to the right to freedom of religion under Article 10? | F26: Article 9 gives Buddhism the foremost place and imposes a duty on the State to protect and foster the Buddha Sasana. However, Article 9 itself qualifies this by stating it is done 'while assuring to all religions the rights granted by Articles 10 and 14(1)(e)'. Article 10 guarantees every person freedom of thought, conscience and religion, including the freedom to have or adopt a religion of their choice. Therefore, the constitutional primacy of Buddhism under Article 9 does not override the individual right to freedom of religion guaranteed under Article 10. | G26: Article 9, Article 10 | H26: Art. 9: The Republic of Sri Lanka shall give to Buddhism Buddhism the foremost place and accordingly it shall be the duty of the State to protect and foster the Buddha Sasana, while assuring to all religions || Art. 10: Every person is entitled to freedom of thought, thought, conscience and religion, including the freedom to have or conscience and religion to adopt a religion or belief of his choice. Freedom | I26: Human Annotated | J26: =MAX(P26,U26,Z26,AE26,AJ26) -> 46170 | K26: LEGAL_EXPERT_1, LEGAL_EXPERT_2, LEGAL_EXPERT_3, LEGAL_EXPERT_4, LEGAL_EXPERT_5 | L26: 4.8 | M26: 4.3 | N26: 4.6 | P26: 2026.05.24 | Q26: 4.8 | R26: 4.4 | S26: 4.6 | U26: 46168 | V26: 4.7 | W26: 4.4 | X26: 4.6 | Z26: 46168 | AA26: 4.5 | AB26: 4.6 | AC26: 4.6 | AE26: 46170 | AF26: 4.7 | AG26: 4.6 | AH26: 4.7 | AJ26: 2026.05.28 | AK26: =AVERAGE(L26,Q26,V26,AA26,AF26) -> 4.7 | AL26: =AVERAGE(M26,R26,W26,AB26,AG26) -> 4.46 | AM26: =AVERAGE(N26,S26,X26,AC26,AH26) -> 4.62
A27: QAC_024 | B27: Interpretive | C27: Hard | D27: Administrative | E27: Do the fundamental duties under Article 28 limit the exercise of fundamental rights? | F27: Article 28 of the Constitution provides that the exercise and enjoyment of rights and freedoms are inseparable from the performance of duties and obligations. The duties listed include upholding the Constitution and law, furthering national interest, and working conscientiously. However, Article 29 makes clear that the provisions of Chapter VI (which includes Article 28) do not confer or impose legally enforceable rights or obligations. Therefore, while Article 28 links rights and duties conceptually, it does not operate as a legal restriction that courts can use to limit the exercise of fundamental rights guaranteed in Chapter III. | G27: Article 28, Article 29 | H27: Art. 28: The exercise and enjoyment of rights and Fundamental freedoms are inseparable from the performance of duties duties and obligations and accordingly it is the duty of every person in Sri Lanka (a) to || Art. 29: The provisions of this Chapter do not confer or Principles of State impose legal rights or obligations and are not enforceable Policy and in any court or tribunal. No question of inconsistency fundame | I27: Human Annotated | J27: =MAX(P27,U27,Z27,AE27,AJ27) -> 46170 | K27: LEGAL_EXPERT_1, LEGAL_EXPERT_2, LEGAL_EXPERT_3, LEGAL_EXPERT_4, LEGAL_EXPERT_5 | L27: 4.8 | M27: 4.3 | N27: 4.6 | P27: 2026.05.24 | Q27: 4.8 | R27: 4.4 | S27: 4.6 | U27: 46168 | V27: 4.7 | W27: 4.4 | X27: 4.6 | Z27: 46168 | AA27: 4.5 | AB27: 4.5 | AC27: 4.5 | AE27: 46170 | AF27: 4.7 | AG27: 4.6 | AH27: 4.7 | AJ27: 2026.05.28 | AK27: =AVERAGE(L27,Q27,V27,AA27,AF27) -> 4.7 | AL27: =AVERAGE(M27,R27,W27,AB27,AG27) -> 4.44 | AM27: =AVERAGE(N27,S27,X27,AC27,AH27) -> 4.6
A28: QAC_025 | B28: Factual | C28: Medium | D28: Criminal | E28: Does the Constitution protect against retrospective criminal penalties? | F28: Yes. Article 13(6) of the Constitution provides that no person shall be held guilty of an offence on account of any act or omission which did not, at the time of such act or omission, constitute such an offence, and no penalty shall be imposed for any offence more severe than the penalty applicable at the time the offence was committed. This prohibition on retrospective penal legislation is a fundamental right under Chapter III. | G28: Article 13 | H28: Art. 13: (1) No person shall be arrested except according Freedom from to procedure established by law. Any person arrested shall arbitrary arrest, be informed of the reason for his arrest. detention and punis | I28: Human Annotated | J28: =MAX(P28,U28,Z28,AE28,AJ28) -> 46170 | K28: LEGAL_EXPERT_1, LEGAL_EXPERT_2, LEGAL_EXPERT_3, LEGAL_EXPERT_4, LEGAL_EXPERT_5 | L28: 4.8 | M28: 4.3 | N28: 4.6 | P28: 2026.05.24 | Q28: 4.8 | R28: 4.4 | S28: 4.6 | U28: 46168 | V28: 4.7 | W28: 4.3 | X28: 4.6 | Z28: 46168 | AA28: 4.7 | AB28: 4.5 | AC28: 4.7 | AE28: 46170 | AF28: 4.7 | AG28: 4.6 | AH28: 4.7 | AJ28: 2026.05.28 | AK28: =AVERAGE(L28,Q28,V28,AA28,AF28) -> 4.74 | AL28: =AVERAGE(M28,R28,W28,AB28,AG28) -> 4.42 | AM28: =AVERAGE(N28,S28,X28,AC28,AH28) -> 4.64
A29: QAC_026 | B29: Factual | C29: Medium | D29: Administrative | E29: What does the Constitution say about Sri Lanka's obligation to ensure social security? | F29: Article 27(9) of the Constitution provides that the State shall ensure social security and welfare. Article 27(2) further pledges the State to promote the welfare of the People by securing and protecting a social order in which justice shall guide all institutions of national life. These are Directive Principles of State Policy under Chapter VI, meaning they guide governance but are not directly enforceable in courts. | G29: Article 27, Article 27 | H29: Art. 27: (3) The State shall safeguard the independence, sovereignty, unity and the territorial integrity of Sri Lanka. (4) The State shall strengthen and broaden the democratic structure of government and the || Art. 27: (3) The State shall safeguard the independence, sovereignty, unity and the territorial integrity of Sri Lanka. (4) The State shall strengthen and broaden the democratic structure of government and the | I29: Human Annotated | J29: =MAX(P29,U29,Z29,AE29,AJ29) -> 46170 | K29: LEGAL_EXPERT_1, LEGAL_EXPERT_2, LEGAL_EXPERT_3, LEGAL_EXPERT_4, LEGAL_EXPERT_5 | L29: 4.8 | M29: 4.3 | N29: 4.6 | P29: 2026.05.24 | Q29: 4.8 | R29: 4.5 | S29: 4.5 | U29: 46168 | V29: 4.8 | W29: 4.5 | X29: 4.5 | Z29: 46168 | AA29: 4.4 | AB29: 4.5 | AC29: 4.6 | AE29: 46170 | AF29: 4.7 | AG29: 4.6 | AH29: 4.7 | AJ29: 2026.05.28 | AK29: =AVERAGE(L29,Q29,V29,AA29,AF29) -> 4.7 | AL29: =AVERAGE(M29,R29,W29,AB29,AG29) -> 4.48 | AM29: =AVERAGE(N29,S29,X29,AC29,AH29) -> 4.58
A30: QAC_027 | B30: Factual | C30: Easy | D30: Constitutional | E30: What is the national flag of Sri Lanka as defined by the Constitution? | F30: Article 6 of the Constitution establishes the National Flag of Sri Lanka as the Lion Flag. | G30: Article 6 | H30: Art. 6: The National Flag of the Republic of Sri Lanka Flag shall be the Lion Flag depicted in the Second Schedule. The National | I30: Human Annotated | J30: =MAX(P30,U30,Z30,AE30,AJ30) -> 46170 | K30: LEGAL_EXPERT_1, LEGAL_EXPERT_2, LEGAL_EXPERT_3, LEGAL_EXPERT_4, LEGAL_EXPERT_5 | L30: 4.8 | M30: 4.3 | N30: 4.6 | P30: 2026.05.24 | Q30: 4.7 | R30: 4.4 | S30: 4.6 | U30: 46168 | V30: 4.6 | W30: 4.3 | X30: 4.5 | Z30: 46168 | AA30: 4.5 | AB30: 4.5 | AC30: 4.5 | AE30: 46170 | AF30: 4.7 | AG30: 4.6 | AH30: 4.7 | AJ30: 2026.05.28 | AK30: =AVERAGE(L30,Q30,V30,AA30,AF30) -> 4.66 | AL30: =AVERAGE(M30,R30,W30,AB30,AG30) -> 4.42 | AM30: =AVERAGE(N30,S30,X30,AC30,AH30) -> 4.58
A31: QAC_028 | B31: Factual | C31: Easy | D31: Constitutional | E31: What is the national anthem of Sri Lanka under the Constitution? | F31: Article 7 of the Constitution declares that the National Anthem of the Republic of Sri Lanka shall be 'Sri Lanka Matha'. | G31: Article 7 | H31: Art. 7: The National Anthem of the Republic of Sri Anthem Lanka shall be Sri Lanka Matha, the words and music of which are set out in the Third Schedule. The National | I31: Human Annotated | J31: =MAX(P31,U31,Z31,AE31,AJ31) -> 46170 | K31: LEGAL_EXPERT_1, LEGAL_EXPERT_2, LEGAL_EXPERT_3, LEGAL_EXPERT_4, LEGAL_EXPERT_5 | L31: 4.8 | M31: 4.3 | N31: 4.6 | P31: 2026.05.24 | Q31: 4.8 | R31: 4.4 | S31: 4.5 | U31: 46168 | V31: 4.8 | W31: 4.4 | X31: 4.6 | Z31: 46168 | AA31: 4.7 | AB31: 4.6 | AC31: 4.7 | AE31: 46170 | AF31: 4.7 | AG31: 4.6 | AH31: 4.7 | AJ31: 2026.05.28 | AK31: =AVERAGE(L31,Q31,V31,AA31,AF31) -> 4.76 | AL31: =AVERAGE(M31,R31,W31,AB31,AG31) -> 4.46 | AM31: =AVERAGE(N31,S31,X31,AC31,AH31) -> 4.62
... A53: QAC_050 | B53: Procedural | C53: Hard | D53: Constitutional | E53: How is the Constitution amended and what special requirements apply to certain provisions? | F53: Article 82 provides the general procedure: a Bill for amendment requires a two-thirds majority of all members of Parliament. Article 83 lists entrenched provisions — including those relating to sovereignty, unitary status, Buddhism (Article 9), and fundamental rights (Articles 10-14) — which additionally require approval by the People at a Referendum after passing with a two-thirds majority in Parliament. | G53: Article 82 | H53: Art. 82: (1) No Bill for the amendment of any provision Amendment or of the Constitution shall be placed on the Order Paper of repeal of the Constitution Parliament, unless the provision to be repealed, altere | I53: Human Annotated | J53: =MAX(P53,U53,Z53,AE53,AJ53) -> 46170 | K53: LEGAL_EXPERT_1, LEGAL_EXPERT_2, LEGAL_EXPERT_3, LEGAL_EXPERT_4, LEGAL_EXPERT_5 | L53: 4.7 | M53: 4.5 | N53: 4.6 | P53: 2026.05.24 | Q53: 4.7 | R53: 4.4 | S53: 4.6 | U53: 46168 | V53: 4.7 | W53: 4.6 | X53: 4.6 | Z53: 46168 | AA53: 4.5 | AB53: 4.5 | AC53: 4.5 | AE53: 46170 | AF53: 4.7 | AG53: 4.6 | AH53: 4.7 | AJ53: 2026.05.28 | AK53: =AVERAGE(L53,Q53,V53,AA53,AF53) -> 4.66 | AL53: =AVERAGE(M53,R53,W53,AB53,AG53) -> 4.52 | AM53: =AVERAGE(N53,S53,X53,AC53,AH53) -> 4.6

Sheet 51-100
A1: Item ID | B1: Query Type | C1: Difficulty | D1: Legal Domain | E1: Question | F1: Reference Answer | G1: Constitutional Articles | H1: Supporting Passage(s) | I1: Annotattion Type | J1: Annotation Date | K1: Reviewer IDs | L1: Reviever 1: Chathuri Madushika (LLB ousl) | Q1: Reviever 2:Rohana Dasanayaka (LLB ousl) | V1: Reviever 3: Dulani Kulasooriya (LLB ousl) | AA1: Reviever 4: Dulshan Liyanaarachchi (LLB ousl) | AF1: Reviever 5: Inoshika Kodithuwakku (LLB ousl) | AK1: Mean | AL1: Mean | AM1: Mean
L2: Reviewer ID: LEGAL_EXPERT_1 | Q2: Reviewer ID: LEGAL_EXPERT_2 | V2: Reviewer ID: LEGAL_EXPERT_3 | AA2: Reviewer ID: LEGAL_EXPERT_4 | AF2: Reviewer ID: LEGAL_EXPERT_5 | AK2: Reviewer IDs: LEGAL_EXPERT_1, LEGAL_EXPERT_2, LEGAL_EXPERT_3, LEGAL_EXPERT_4, LEGAL_EXPERT_5
L3: Correctness (1=Poor 5=Excellent) | M3: Completeness (1=Poor 5=Excellent) | N3: Clarity (1=Poor 5=Excellent) | O3: Expert Comments | P3: Review Date | Q3: Correctness (1=Poor 5=Excellent) | R3: Completeness (1=Poor 5=Excellent) | S3: Clarity (1=Poor 5=Excellent) | T3: Expert Comments | U3: Review Date | V3: Correctness (1=Poor 5=Excellent) | W3: Completeness (1=Poor 5=Excellent) | X3: Clarity (1=Poor 5=Excellent) | Y3: Expert Comments | Z3: Review Date | AA3: Correctness (1=Poor 5=Excellent) | AB3: Completeness (1=Poor 5=Excellent) | AC3: Clarity (1=Poor 5=Excellent) | AD3: Expert Comments | AE3: Review Date | AF3: Correctness (1=Poor 5=Excellent) | AG3: Completeness (1=Poor 5=Excellent) | AH3: Clarity (1=Poor 5=Excellent) | AI3: Expert Comments | AJ3: Review Date | AK3: Correctness (1=Poor 5=Excellent) | AL3: Completeness (1=Poor 5=Excellent) | AM3: Clarity (1=Poor 5=Excellent)
A4: QAC_051 | B4: Factual | C4: Medium | D4: Constitutional | E4: What courts constitute the judicial system of Sri Lanka under the Constitution? | F4: Article 105 of the Constitution establishes the judicial system comprising: the Supreme Court of the Republic of Sri Lanka, the Court of Appeal, the High Court, and such other courts as Parliament may provide. The Supreme Court is the highest and final court. | G4: Article 105 | H4: Art. 105: (1) Subject to the provisions of the E s t a b lishment of Courts, & c. Constitution, the institutions for the administration of justice which protect, vindicate and enforce the rights of the People s | I4: Human Annotated | J4: =MAX(P4,U4,Z4,AE4,AJ4) -> 46170 | K4: LEGAL_EXPERT_1, LEGAL_EXPERT_2, LEGAL_EXPERT_3, LEGAL_EXPERT_4, LEGAL_EXPERT_5 | L4: 4.5 | M4: 4.3 | N4: 4.8 | P4: 2026.05.25 | Q4: 4.5 | R4: 4.3 | S4: 4.8 | U4: 2026.05.27 | V4: 4.7 | W4: 4.7 | X4: 4.6 | Z4: 46168 | AA4: 4.7 | AB4: 4.8 | AC4: 4.7 | AE4: 46170 | AF4: 4.7 | AG4: 4.8 | AH4: 4.7 | AJ4: 2026.05.28 | AK4: =AVERAGE(L4,Q4,V4,AA4,AF4) -> 4.62 | AL4: =AVERAGE(M4,R4,W4,AB4,AG4) -> 4.58 | AM4: =AVERAGE(N4,S4,X4,AC4,AH4) -> 4.72
A5: QAC_052 | B5: Factual | C5: Medium | D5: Constitutional | E5: What is the jurisdiction of the Supreme Court of Sri Lanka? | F5: Article 118 of the Constitution confers on the Supreme Court jurisdiction in respect of: constitutional matters; protection of fundamental rights; final appellate jurisdiction; consultative jurisdiction; jurisdiction in election petitions; jurisdiction in respect of breaches of Parliamentary privileges; and such other jurisdiction as Parliament may provide. | G5: Article 118 | H5: Art. 118: The Supreme Court of the Republic of Sri jurisdiction of Supreme Lanka shall be the highest and final superior Court of Court record in the Republic and shall subject to the provisions of the Constitu | I5: Human Annotated | J5: =MAX(P5,U5,Z5,AE5,AJ5) -> 46170 | K5: LEGAL_EXPERT_1, LEGAL_EXPERT_2, LEGAL_EXPERT_3, LEGAL_EXPERT_4, LEGAL_EXPERT_5 | L5: 4.5 | M5: 4.3 | N5: 4.8 | P5: 2026.05.25 | Q5: 4.5 | R5: 4.3 | S5: 4.7 | U5: 2026.05.27 | V5: 4.3 | W5: 4.4 | X5: 4.6 | Z5: 46168 | AA5: 4.4 | AB5: 4.5 | AC5: 4.6 | AE5: 46170 | AF5: 4.4 | AG5: 4.5 | AH5: 4.6 | AJ5: 2026.05.28 | AK5: =AVERAGE(L5,Q5,V5,AA5,AF5) -> 4.42 | AL5: =AVERAGE(M5,R5,W5,AB5,AG5) -> 4.4 | AM5: =AVERAGE(N5,S5,X5,AC5,AH5) -> 4.66
A6: QAC_053 | B6: Factual | C6: Medium | D6: Constitutional | E6: Who has exclusive jurisdiction to interpret the Constitution? | F6: Article 125 of the Constitution confers on the Supreme Court sole and exclusive jurisdiction to hear and determine any question relating to the interpretation of the Constitution. Any such question arising in the course of proceedings in any other court or tribunal shall be referred to the Supreme Court for determination. | G6: Article 125 | H6: Art. 125: (1) The Supreme Court shall have sole and Constitutional exclusive jurisdiction to hear and determine any question jurisdiction in the relating to the interpretation of the Constitution and interpreta | I6: Human Annotated | J6: =MAX(P6,U6,Z6,AE6,AJ6) -> 46170 | K6: LEGAL_EXPERT_1, LEGAL_EXPERT_2, LEGAL_EXPERT_3, LEGAL_EXPERT_4, LEGAL_EXPERT_5 | L6: 4.5 | M6: 4.3 | N6: 4.8 | P6: 2026.05.25 | Q6: 4.5 | R6: 4.2 | S6: 4.8 | U6: 2026.05.27 | V6: 4.6 | W6: 4.4 | X6: 4.7 | Z6: 46168 | AA6: 4.6 | AB6: 4.7 | AC6: 4.5 | AE6: 46170 | AF6: 4.6 | AG6: 4.7 | AH6: 4.5 | AJ6: 2026.05.28 | AK6: =AVERAGE(L6,Q6,V6,AA6,AF6) -> 4.56 | AL6: =AVERAGE(M6,R6,W6,AB6,AG6) -> 4.46 | AM6: =AVERAGE(N6,S6,X6,AC6,AH6) -> 4.66
A7: QAC_054 | B7: Procedural | C7: Hard | D7: Constitutional | E7: What is the process for enforcing fundamental rights in the Supreme Court? | F7: Article 126 of the Constitution provides that every person shall have the right to apply directly to the Supreme Court for relief or redress in respect of the infringement or imminent infringement of a fundamental right guaranteed by Chapter III. The Supreme Court shall have the power to grant such relief or make such directions as it deems appropriate. | G7: Article 126 | H7: Art. 126: (1) The Supreme Court shall have sole and rights exclusive jurisdiction to hear and determine any question jurisdiction and its relating to the infringement or imminent infringement by exercise execut | I7: Human Annotated | J7: =MAX(P7,U7,Z7,AE7,AJ7) -> 46170 | K7: LEGAL_EXPERT_1, LEGAL_EXPERT_2, LEGAL_EXPERT_3, LEGAL_EXPERT_4, LEGAL_EXPERT_5 | L7: 4.5 | M7: 4.3 | N7: 4.8 | P7: 2026.05.25 | Q7: 4.4 | R7: 4.3 | S7: 4.8 | U7: 2026.05.27 | V7: 4.7 | W7: 4.4 | X7: 4.5 | Z7: 46168 | AA7: 4.9 | AB7: 4.8 | AC7: 4.7 | AE7: 46170 | AF7: 4.7 | AG7: 4.8 | AH7: 4.7 | AJ7: 2026.05.28 | AK7: =AVERAGE(L7,Q7,V7,AA7,AF7) -> 4.64 | AL7: =AVERAGE(M7,R7,W7,AB7,AG7) -> 4.52 | AM7: =AVERAGE(N7,S7,X7,AC7,AH7) -> 4.7
A8: QAC_055 | B8: Factual | C8: Medium | D8: Constitutional | E8: What is the appellate jurisdiction of the Court of Appeal? | F8: Article 138 of the Constitution confers on the Court of Appeal appellate jurisdiction for the correction of errors in fact or law committed by all courts of first instance. The Court of Appeal may affirm, reverse or vary any judgment, decree, order or sentence of the court from which the appeal is taken. | G8: Article 138 | H8: Art. 138: Jurisdiction 138. (1) The Court of Appeal shall have and of the Court exercise subject to the provisions of the Constitution or of Appeal of any law, an appellate jurisdiction for the correction of al | I8: Human Annotated | J8: =MAX(P8,U8,Z8,AE8,AJ8) -> 46170 | K8: LEGAL_EXPERT_1, LEGAL_EXPERT_2, LEGAL_EXPERT_3, LEGAL_EXPERT_4, LEGAL_EXPERT_5 | L8: 4.5 | M8: 4.3 | N8: 4.8 | P8: 2026.05.25 | Q8: 4.5 | R8: 4.3 | S8: 4.8 | U8: 2026.05.27 | V8: 4.6 | W8: 4.4 | X8: 4.7 | Z8: 46168 | AA8: 4.5 | AB8: 4.4 | AC8: 4.8 | AE8: 46170 | AF8: 4.4 | AG8: 4.5 | AH8: 4.6 | AJ8: 2026.05.28 | AK8: =AVERAGE(L8,Q8,V8,AA8,AF8) -> 4.5 | AL8: =AVERAGE(M8,R8,W8,AB8,AG8) -> 4.38 | AM8: =AVERAGE(N8,S8,X8,AC8,AH8) -> 4.74
A9: QAC_056 | B9: Factual | C9: Medium | D9: Constitutional | E9: What is the Consolidated Fund and how are withdrawals controlled? | F9: Article 148 of the Constitution establishes Parliament's control over public finance: all revenues, grants and other moneys shall form the Consolidated Fund. Article 150 provides that no sum shall be withdrawn from the Consolidated Fund except under the authority of a warrant signed by the Minister of Finance, and only where Parliament has appropriated the sum for specified public services. | G9: Article 148 | H9: Art. 148: Parliament shall have full control over public Control of finance. No tax, rate or any other levy shall be imposed by Parliament over public any local authority or any other public authority, except f | I9: Human Annotated | J9: =MAX(P9,U9,Z9,AE9,AJ9) -> 46170 | K9: LEGAL_EXPERT_1, LEGAL_EXPERT_2, LEGAL_EXPERT_3, LEGAL_EXPERT_4, LEGAL_EXPERT_5 | L9: 4.5 | M9: 4.3 | N9: 4.8 | P9: 2026.05.25 | Q9: 4.5 | R9: 4.3 | S9: 4.7 | U9: 2026.05.27 | V9: 4.8 | W9: 4.4 | X9: 4.5 | Z9: 46168 | AA9: 4.7 | AB9: 4.5 | AC9: 4.5 | AE9: 46170 | AF9: 4.6 | AG9: 4.7 | AH9: 4.5 | AJ9: 2026.05.28 | AK9: =AVERAGE(L9,Q9,V9,AA9,AF9) -> 4.62 | AL9: =AVERAGE(M9,R9,W9,AB9,AG9) -> 4.44 | AM9: =AVERAGE(N9,S9,X9,AC9,AH9) -> 4.6
A10: QAC_057 | B10: Factual | C10: Medium | D10: Constitutional | E10: What is the Appropriation Bill and when must it be presented to Parliament? | F10: Under Article 152 of the Constitution, no Bill or motion authorizing the disposal of funds from the Consolidated Fund or the imposition, repeal, or reduction of any tax may be introduced in Parliament except by a Minister, and only if the Bill has been approved by the Cabinet of Ministers. The Appropriation Bill, which authorizes annual government expenditure, must accordingly be presented by the Minister in charge of Finance. Parliament must approve the Appropriation Bill before funds can be drawn from the Consolidated Fund under Articles 149 and 150. | G10: Article 152 | H10: Art. 152: No Bill or motion, authorizing the disposal of, or provisions the imposition of charges upon, the Consolidated Fund or a | I10: Human Annotated | J10: =MAX(P10,U10,Z10,AE10,AJ10) -> 46170 | K10: LEGAL_EXPERT_1, LEGAL_EXPERT_2, LEGAL_EXPERT_3, LEGAL_EXPERT_4, LEGAL_EXPERT_5 | L10: 4.5 | M10: 4.3 | N10: 4.8 | P10: 2026.05.25 | Q10: 4.5 | R10: 4.4 | S10: 4.8 | U10: 2026.05.27 | V10: 4.9 | W10: 4.7 | X10: 4.6 | Z10: 46168 | AA10: 4.7 | AB10: 4.7 | AC10: 4.7 | AE10: 46170 | AF10: 4.7 | AG10: 4.8 | AH10: 4.7 | AJ10: 2026.05.28 | AK10: =AVERAGE(L10,Q10,V10,AA10,AF10) -> 4.66 | AL10: =AVERAGE(M10,R10,W10,AB10,AG10) -> 4.58 | AM10: =AVERAGE(N10,S10,X10,AC10,AH10) -> 4.72
A11: QAC_058 | B11: Factual | C11: Medium | D11: Constitutional | E11: What is the role of the Auditor General under the Constitution? | F11: Article 154 of the Constitution requires the Auditor-General to audit the accounts of all departments of Government, the Office of the Secretary to the President, the Office of the Secretary to the Prime Minister, and all public corporations and local authorities. The Auditor-General is required to report to Parliament on the accounts audited. | G11: Article 154 | H11: Art. 153H: 154. [(1) The Auditor-General shall audit all Duties and departments of the Government, the Office of the Secretary to t | I11: Human Annotated | J11: =MAX(P11,U11,Z11,AE11,AJ11) -> 46170 | K11: LEGAL_EXPERT_1, LEGAL_EXPERT_2, LEGAL_EXPERT_3, LEGAL_EXPERT_4, LEGAL_EXPERT_5 | L11: 4.5 | M11: 4.3 | N11: 4.8 | P11: 2026.05.25 | Q11: 4.5 | R11: 4.3 | S11: 4.8 | U11: 2026.05.27 | V11: 4.8 | W11: 4.5 | X11: 4.6 | Z11: 46168 | AA11: 4.5 | AB11: 4.5 | AC11: 4.7 | AE11: 46170 | AF11: 4.4 | AG11: 4.5 | AH11: 4.6 | AJ11: 2026.05.28 | AK11: =AVERAGE(L11,Q11,V11,AA11,AF11) -> 4.54 | AL11: =AVERAGE(M11,R11,W11,AB11,AG11) -> 4.42 | AM11: =AVERAGE(N11,S11,X11,AC11,AH11) -> 4.7
A12: QAC_059 | B12: Procedural | C12: Hard | D12: Constitutional | E12: Under what circumstances may a state of emergency be declared? | F12: Article 155 of the Constitution provides that the President may by Proclamation declare a state of emergency when the President is of opinion that a public emergency exists. Emergency regulations made thereunder must be laid before Parliament and cease to be in force after 30 days unless Parliament approves them by resolution. | G12: Article 155 | H12: Art. 155: (1) The Public Security Ordinance as amended Public Security and in force immediately prior to the commencement of the Constitution shall be deemed to be a law enacted by Parliament. (2) The power to | I12: Human Annotated | J12: =MAX(P12,U12,Z12,AE12,AJ12) -> 46170 | K12: LEGAL_EXPERT_1, LEGAL_EXPERT_2, LEGAL_EXPERT_3, LEGAL_EXPERT_4, LEGAL_EXPERT_5 | L12: 4.5 | M12: 4.3 | N12: 4.8 | P12: 2026.05.25 | Q12: 4.6 | R12: 4.3 | S12: 4.8 | U12: 2026.05.27 | V12: 4.5 | W12: 4.2 | X12: 4.5 | Z12: 46168 | AA12: 4.7 | AB12: 4.6 | AC12: 4.5 | AE12: 46170 | AF12: 4.6 | AG12: 4.7 | AH12: 4.5 | AJ12: 2026.05.28 | AK12: =AVERAGE(L12,Q12,V12,AA12,AF12) -> 4.58 | AL12: =AVERAGE(M12,R12,W12,AB12,AG12) -> 4.42 | AM12: =AVERAGE(N12,S12,X12,AC12,AH12) -> 4.62
A13: QAC_060 | B13: Factual | C13: Hard | D13: Constitutional | E13: What is the Finance Commission and what is its role? | F13: Article 154R of the Constitution establishes the Finance Commission, which is responsible for making recommendations to the President regarding the allocation of funds from the Annual Budget to meet the needs of the Provinces and ensuring equitable distribution of financial resources among the Provinces. | G13: Article 154R | H13: Art. 154R: (1) There shall be a Finance Commission Commission consisting of (a) the Governor of the Central Bank of Sri Lanka; The Constitution of the Democratic Socialist Republic of Sri Lanka 177 (b) the Secr | I13: Human Annotated | J13: =MAX(P13,U13,Z13,AE13,AJ13) -> 46170 | K13: LEGAL_EXPERT_1, LEGAL_EXPERT_2, LEGAL_EXPERT_3, LEGAL_EXPERT_4, LEGAL_EXPERT_5 | L13: 4.5 | M13: 4.3 | N13: 4.8 | P13: 2026.05.25 | Q13: 4.5 | R13: 4.3 | S13: 4.8 | U13: 2026.05.27 | V13: 4.6 | W13: 4.5 | X13: 4.6 | Z13: 46168 | AA13: 4.5 | AB13: 4.5 | AC13: 4.5 | AE13: 46170 | AF13: 4.7 | AG13: 4.8 | AH13: 4.7 | AJ13: 2026.05.28 | AK13: =AVERAGE(L13,Q13,V13,AA13,AF13) -> 4.56 | AL13: =AVERAGE(M13,R13,W13,AB13,AG13) -> 4.48 | AM13: =AVERAGE(N13,S13,X13,AC13,AH13) -> 4.68
A14: QAC_061 | B14: Factual | C14: Medium | D14: Constitutional | E14: What are the qualifications to be registered as an elector? | F14: Article 88 provides that every person, unless disqualified as provided, shall be qualified to be an elector at the election of the President and Members of Parliament and to vote at any Referendum, provided that their name is entered in the appropriate register of electors. Article 89(b) further provides that no person shall be qualified to be an elector if they have not attained the age of eighteen years on the qualifying date specified by law. Article 88 thus sets the general entitlement and Article 89 sets the disqualifications, including the minimum voting age. | G14: Article 88, Article 89 | H14: Art. 88: Every person shall, unless disqualified as elector hereinafter provided, be qualified to be an elector at the election of the President and of the Members of Parliament or to vote at any Referendum: P || Art. 89: No person shall be qualified to be an elector to be an elector at an election of the President, or of the Members of Parliament or to vote at any Referendum, if he is subject to any of the following d | I14: Human Annotated | J14: =MAX(P14,U14,Z14,AE14,AJ14) -> 46170 | K14: LEGAL_EXPERT_1, LEGAL_EXPERT_2, LEGAL_EXPERT_3, LEGAL_EXPERT_4, LEGAL_EXPERT_5 | L14: 4.5 | M14: 4.3 | N14: 4.8 | P14: 2026.05.25 | Q14: 4.5 | R14: 4.3 | S14: 4.7 | U14: 2026.05.27 | V14: 4.5 | W14: 4.4 | X14: 4.6 | Z14: 46168 | AA14: 4.4 | AB14: 4.6 | AC14: 4.6 | AE14: 46170 | AF14: 4.4 | AG14: 4.5 | AH14: 4.6 | AJ14: 2026.05.28 | AK14: =AVERAGE(L14,Q14,V14,AA14,AF14) -> 4.46 | AL14: =AVERAGE(M14,R14,W14,AB14,AG14) -> 4.42 | AM14: =AVERAGE(N14,S14,X14,AC14,AH14) -> 4.66
A15: QAC_062 | B15: Factual | C15: Medium | D15: Constitutional | E15: What disqualifies a person from being elected as a Member of Parliament? | F15: Article 91 of the Constitution lists the disqualifications for membership of Parliament, including: being a citizen of another country, being an undischarged bankrupt, having been sentenced to imprisonment for two years or more, holding a disqualifying office of profit, and such other grounds as Parliament may provide. | G15: Article 91 | H15: Art. 91: (1) No person shall be qualified to be elected as a for election as Member of Parliament or to sit and vote in Parliament a Member of Parliament (a) if he is or becomes subject to any of the disquali | I15: Human Annotated | J15: =MAX(P15,U15,Z15,AE15,AJ15) -> 46170 | K15: LEGAL_EXPERT_1, LEGAL_EXPERT_2, LEGAL_EXPERT_3, LEGAL_EXPERT_4, LEGAL_EXPERT_5 | L15: 4.5 | M15: 4.3 | N15: 4.8 | P15: 2026.05.25 | Q15: 4.5 | R15: 4.3 | S15: 4.8 | U15: 2026.05.27 | V15: 4.6 | W15: 4.5 | X15: 4.7 | Z15: 46168 | AA15: 4.7 | AB15: 4.6 | AC15: 4.5 | AE15: 46170 | AF15: 4.6 | AG15: 4.7 | AH15: 4.5 | AJ15: 2026.05.28 | AK15: =AVERAGE(L15,Q15,V15,AA15,AF15) -> 4.58 | AL15: =AVERAGE(M15,R15,W15,AB15,AG15) -> 4.48 | AM15: =AVERAGE(N15,S15,X15,AC15,AH15) -> 4.66
... A18: QAC_065 | B18: Interpretive | C18: Hard | D18: Constitutional | E18: What are the directive principles of state policy in the Constitution? | F18: Article 27 of the Constitution sets out the Directive Principles of State Policy. These are not legally enforceable rights but are principles guiding legislation. They include: establishing a democratic socialist society; ensuring the right to work; equal rights for women; protection of the family; free education; and adequate standard of living. | G18: Article 27 | H18: Art. 27: (1) The Directive Principles of State Policy Directive Principles herein contained shall guide Parliament, the President of State and the Cabinet of Ministers in the enactment of laws and Policy the g | I18: Human Annotated | J18: =MAX(P18,U18,Z18,AE18,AJ18) -> 46170 | K18: LEGAL_EXPERT_1, LEGAL_EXPERT_2, LEGAL_EXPERT_3, LEGAL_EXPERT_4, LEGAL_EXPERT_5 | L18: 4.5 | M18: 4.3 | N18: 4.8 | P18: 2026.05.25 | Q18: 4.5 | R18: 4.3 | S18: 4.8 | U18: 2026.05.27 | V18: 4.5 | W18: 4.4 | X18: 4.5 | Z18: 46168 | AA18: 4.4 | AB18: 4.5 | AC18: 4.4 | AE18: 46170 | AF18: 4.6 | AG18: 4.7 | AH18: 4.5 | AJ18: 2026.05.28 | AK18: =AVERAGE(L18,Q18,V18,AA18,AF18) -> 4.5 | AL18: =AVERAGE(M18,R18,W18,AB18,AG18) -> 4.44 | AM18: =AVERAGE(N18,S18,X18,AC18,AH18) -> 4.6
A19: QAC_066 | B19: Interpretive | C19: Hard | D19: Constitutional | E19: What restrictions can be placed on fundamental rights under the Constitution? | F19: Article 15 of the Constitution permits restrictions on the exercise of fundamental rights. The rights guaranteed by Articles 13 and 14 may be restricted by law in the interests of: national security, public order, the protection of public health or morality, or for the purpose of securing due recognition of the rights and freedoms of others. | G19: Article 15 | H19: Art. 15: (1) The exercise and operation of the fundamental fundamental rights declared and recognized by Articles rights 13(5) and 13(6) shall be subject only to such restrictions as may be prescribed by law i | I19: Human Annotated | J19: =MAX(P19,U19,Z19,AE19,AJ19) -> 46170 | K19: LEGAL_EXPERT_1, LEGAL_EXPERT_2, LEGAL_EXPERT_3, LEGAL_EXPERT_4, LEGAL_EXPERT_5 | L19: 4.5 | M19: 4.3 | N19: 4.8 | P19: 2026.05.25 | Q19: 4.3 | R19: 4.4 | S19: 4.8 | U19: 2026.05.27 | V19: .4.7 | W19: 4.3 | X19: 4.6 | Z19: 46168 | AA19: 4.8 | AB19: 4.5 | AC19: 4.5 | AE19: 46170 | AF19: 4.7 | AG19: 4.8 | AH19: 4.7 | AJ19: 2026.05.28 | AK19: =AVERAGE(L19,Q19,V19,AA19,AF19) -> 4.575 | AL19: =AVERAGE(M19,R19,W19,AB19,AG19) -> 4.46 | AM19: =AVERAGE(N19,S19,X19,AC19,AH19) -> 4.68
A20: QAC_067 | B20: Interpretive | C20: Hard | D20: Constitutional | E20: Can Parliament delegate its legislative power to another body? | F20: Article 76(1) of the Constitution provides that Parliament shall not abdicate or in any manner alienate its legislative power, and shall not set up any authority with any legislative power. However, Parliament may delegate to subordinate bodies the power to make regulations, rules, by-laws and other subordinate legislation in accordance with law. | G20: Article 76 | H20: Art. 76: (1) Parliament shall not abdicate or in any legislative manner alienate its legislative power and shall not set up power any authority with any legislative power. (2) It shall not be a contravention o | I20: Human Annotated | J20: =MAX(P20,U20,Z20,AE20,AJ20) -> 46170 | K20: LEGAL_EXPERT_1, LEGAL_EXPERT_2, LEGAL_EXPERT_3, LEGAL_EXPERT_4, LEGAL_EXPERT_5 | L20: 4.5 | M20: 4.3 | N20: 4.8 | P20: 2026.05.25 | Q20: 4.5 | R20: 4.3 | S20: 4.8 | U20: 2026.05.27 | V20: 4.8 | W20: 4.4 | X20: 4.6 | Z20: 46168 | AA20: 4.6 | AB20: 4.5 | AC20: 4.4 | AE20: 46170 | AF20: 4.4 | AG20: 4.5 | AH20: 4.6 | AJ20: 2026.05.28 | AK20: =AVERAGE(L20,Q20,V20,AA20,AF20) -> 4.56 | AL20: =AVERAGE(M20,R20,W20,AB20,AG20) -> 4.4 | AM20: =AVERAGE(N20,S20,X20,AC20,AH20) -> 4.64
